Workbook

Sheet Draft HQ
A1: AMERESCO'S BEST — 2026 DRAFT HQ v2
A2: Live value signal • exposure alerts • tier scarcity • rival threat • phase strategy • next-entry guidance
A4: LIVE ROOM CONTROL | D4: CURRENT NOMINATION - SELECT FROM DROPDOWN | H4: POSITION BUDGET | L4: STRONGEST RIVAL
A5: Starting budget | B5: 200 | D5: Player | H5: Position | I5: Plan | J5: Actual | K5: Variance | L5: Team | M5: =INDEX('Team Tracker'!$A$6:$A$18,MATCH(MAX('Team Tracker'!$G$6:$G$18),'Team Tracker'!$G$6:$G$18,0)) -> RD
A6: My spend | B6: =SUMIF('Auction Log'!$D$5:$D$304,"ME",'Auction Log'!$E$5:$E$304) -> 0 | D6: Value vs Market | E6: =IFERROR(INDEX('Player Board'!$B$5:$B$304,MATCH(E5,'Player Board'!$A$5:$A$304,0)),"") | F6: Signal | G6: =IFERROR(INDEX('Player Board'!$C$5:$C$304,MATCH(E5,'Player Board'!$A$5:$A$304,0)),"") | H6: QB | I6: 9 | J6: =SUMIFS('Auction Log'!$E$5:$E$304,'Auction Log'!$D$5:$D$304,"ME",'Auction Log'!$C$5:$C$304,H6) -> 0 | K6: =I6-J6 -> 9 | L6: Max bid | M6: =MAX('Team Tracker'!$G$6:$G$18) -> 186
A7: Budget left | B7: =B5-B6 -> 200 | D7: Market | E7: =IFERROR(INDEX('Player Board'!$N$5:$N$304,MATCH(E5,'Player Board'!$A$5:$A$304,0)),"") | F7: Target | G7: =IFERROR(INDEX('Player Board'!$S$5:$S$304,MATCH(E5,'Player Board'!$A$5:$A$304,0)),"") | H7: RB | I7: 90 | J7: =SUMIFS('Auction Log'!$E$5:$E$304,'Auction Log'!$D$5:$D$304,"ME",'Auction Log'!$C$5:$C$304,H7) -> 0 | K7: =I7-J7 -> 90 | L7: Slots left | M7: =INDEX('Team Tracker'!$F$6:$F$18,MATCH(M5,'Team Tracker'!$A$6:$A$18,0)) -> 15
A8: Players won | B8: =COUNTIF('Auction Log'!$D$5:$D$304,"ME") -> 0 | D8: Stop price | E8: =IFERROR(INDEX('Player Board'!$R$5:$R$304,MATCH(E5,'Player Board'!$A$5:$A$304,0)),"") | F8: SAFE BID | G8: =IF(E5="","",IF(E9<>"Available",0,MIN($B$10,ROUND(E8*$B$13,0)))) | H8: WR | I8: 88 | J8: =SUMIFS('Auction Log'!$E$5:$E$304,'Auction Log'!$D$5:$D$304,"ME",'Auction Log'!$C$5:$C$304,H8) -> 0 | K8: =I8-J8 -> 88 | L8: Need to drain | M8: =INDEX('Team Tracker'!$N$6:$N$18,MATCH(M5,'Team Tracker'!$A$6:$A$18,0)) -> RB
A9: Slots left | B9: =15-B8 -> 15 | D9: Status | E9: =IFERROR(INDEX('Player Board'!$D$5:$D$304,MATCH(E5,'Player Board'!$A$5:$A$304,0)),"") | F9: Nomination | G9: =IFERROR(INDEX('Player Board'!$T$5:$T$304,MATCH(E5,'Player Board'!$A$5:$A$304,0)),"") | H9: TE | I9: 11 | J9: =SUMIFS('Auction Log'!$E$5:$E$304,'Auction Log'!$D$5:$D$304,"ME",'Auction Log'!$C$5:$C$304,H9) -> 0 | K9: =I9-J9 -> 11 | L9: Threat | M9: =IF(M6>50,"HIGH",IF(M6>25,"MODERATE","LOW")) -> HIGH
A10: Legal max bid | B10: =IF(B9=0,0,B7-B9+1) -> 186 | D10: Injury / news | E10: =IFERROR(INDEX('Player Board'!$U$5:$U$304,MATCH(E5,'Player Board'!$A$5:$A$304,0)),"") | H10: D/ST | I10: 1 | J10: =SUMIFS('Auction Log'!$E$5:$E$304,'Auction Log'!$D$5:$D$304,"ME",'Auction Log'!$C$5:$C$304,H10) -> 0 | K10: =I10-J10 -> 1 | L10: Action | M10: ="Nominate "&M8&" to drain cash" -> Nominate RB to drain cash
A11: Room dollars left | B11: =SUM('Team Tracker'!$D$5:$D$18) -> 2800 | H11: K | I11: 1 | J11: =SUMIFS('Auction Log'!$E$5:$E$304,'Auction Log'!$D$5:$D$304,"ME",'Auction Log'!$C$5:$C$304,H11) -> 0 | K11: =I11-J11 -> 1
A12: Pool value left | B12: =SUMIFS('Player Board'!$R$5:$R$304,'Player Board'!$D$5:$D$304,"Available",'Player Board'!$W$5:$W$304,"YES") -> 2800 | D12: =IF(E5="","SELECT CURRENT NOMINATION FROM DROPDOWN",IF(E9<>"Available","SOLD - select next nomination",IF(E6>=5,"SMASH BUY - bid assertively up to SAFE BID",IF(E6>=2,"BUY - Target or below",IF(E6>=-1,"NEUTRAL - only at Target",IF(E6>=-4,"AVOID - demand a discount","DO NOT BID")))))) -> SELECT CURRENT NOMINATION FROM DROPDOWN
A13: Inflation | B13: =IFERROR(B11/B12,1) -> 1
A14: DRAFT PROGRESS | D14: DYNAMIC GAME FLOW | H14: POSITION HEALTH & REMAINING NEEDS
A15: Nominations completed | B15: =COUNTIF('Auction Log'!$B$5:$B$304,"<>") -> 0 | D15: Phase status | E15: =IF(B15=0,"READY",B17&" — "&B15&" nominations logged") -> READY | H15: Position | I15: Owned | J15: Target | K15: Needed | L15: Status
A16: Estimated time left | B16: =MAX(0,(210-B15)*0.83/1440) -> 0.12104167 | D16: Market state | E16: =IF(B13>1.1,"HEATING UP",IF(B13>=1,"NEUTRAL","DEFLATING")) -> NEUTRAL | H16: QB | I16: ='Team Tracker'!H5 -> 0 | J16: 1 | K16: =MAX(0,J16-I16) -> 1 | L16: =IF(I16>=J16,"SET",IF($B$15>=60,"CRITICAL — fill now","NEED "&K16)) -> NEED 1
A17: Current phase | B17: =IF(B15<=20,"OPENING",IF(B15<=90,"MIDDLE",IF(B15<150,"LATE","ENDGAME"))) -> OPENING | D17: Recommended | E17: =IF(B13>1.1,"Room underspent; remaining prices are rising. Buy scarce targets before tiers close.",IF(B13>=1,"Neutral market. Buy at Target or below with confidence.","Room overspent; remaining players are deflating. Stay patient and obey SAFE BID.")) -> Neutral market. Buy at Target or below with confidence. | H17: RB | I17: ='Team Tracker'!I5 -> 0 | J17: 5 | K17: =MAX(0,J17-I17) -> 5 | L17: =IF(I17>=5,"SET",IF(AND($B$15>=60,I17<4),"CRITICAL — need "&K17,IF(AND($B$15>=30,I17<3),"HIGH ALERT — need "&K17,"NEED "&K17))) -> NEED 5
A18: Last sale | B18: =IF(B15=0,"—",INDEX('Auction Log'!$B$5:$B$304,MATCH(B15,'Auction Log'!$A$5:$A$304,0))) -> — | H18: WR | I18: ='Team Tracker'!J5 -> 0 | J18: 5 | K18: =MAX(0,J18-I18) -> 5 | L18: =IF(I18>=5,"SET",IF(AND($B$15>=60,I18<4),"CRITICAL — need "&K18,IF(AND($B$15>=30,I18<3),"HIGH ALERT — need "&K18,"NEED "&K18))) -> NEED 5
H19: TE | I19: ='Team Tracker'!K5 -> 0 | J19: 1 | K19: =MAX(0,J19-I19) -> 1 | L19: =IF(I19>=1,"SET",IF($B$15>=90,"HIGH ALERT","NEED 1")) -> NEED 1
H20: D/ST | I20: ='Team Tracker'!L5 -> 0 | J20: 1 | K20: =MAX(0,J20-I20) -> 1 | L20: =IF(I20>=1,"SET",IF($B$15<150,"WAIT — reserve $1","NEED 1 NOW")) -> WAIT — reserve $1
H21: K | I21: ='Team Tracker'!M5 -> 0 | J21: 1 | K21: =MAX(0,J21-I21) -> 1 | L21: =IF(I21>=1,"SET",IF($B$15<150,"WAIT — reserve $1","NEED 1 NOW")) -> WAIT — reserve $1
H22: =IF(AND($B$15>=60,I17<4),"RB DEPTH CRITICAL — prioritize the next value RB",IF(AND($B$15>=30,I17<3),"RB DEPTH HIGH ALERT — need volume",IF(AND($B$15>=60,I18<4),"WR DEPTH CRITICAL — prioritize the next value WR",IF(AND($B$15>=30,I18<3),"WR DEPTH HIGH ALERT — need targets","POSITION HEALTH ON TRACK")))) -> POSITION HEALTH ON TRACK
A24: STAR TRACKER — TOP AVAILABLE BY VALUE TIER | G24: ENDGAME MUST-HAVES
A25: Tier | B25: Ceiling band | C25: Left | D25: Top three available | G25: Player | H25: Pos | I25: Target | J25: Max | K25: Status | L25: Sold | M25: Action
A26: TIER 1 | B26: $55+ | C26: =COUNTIFS('Player Board'!$R$5:$R$304,">=55",'Player Board'!$D$5:$D$304,"Available") -> 7 | D26: =IF(C26=0,"—",IFERROR(INDEX('Player Board'!$A$5:$A$304,SMALL('Player Board'!$X$5:$X$304,1)-4),"")&IF(C26>1,CHAR(10)&IFERROR(INDEX('Player Board'!$A$5:$A$304,SMALL('Player Board'!$X$5:$X$304,2)-4),""),"")&IF(C26>2,CHAR(10)&IFERROR(INDEX('Player Board'!$A$5:$A$304,SMALL('Player Board'!$X$5:$X$304,3)-4),""),"")) -> Jahmyr Gibbs Ja'Marr Chase Bijan Robinson | G26: Matthew Stafford | H26: =IFERROR(INDEX('Player Board'!$G$5:$G$304,MATCH(G26,'Player Board'!$A$5:$A$304,0)),"") -> QB | I26: =IFERROR(INDEX('Player Board'!$S$5:$S$304,MATCH(G26,'Player Board'!$A$5:$A$304,0)),"") -> 8 | J26: =IFERROR(INDEX('Player Board'!$R$5:$R$304,MATCH(G26,'Player Board'!$A$5:$A$304,0)),"") -> 10 | K26: =IFERROR(INDEX('Player Board'!$D$5:$D$304,MATCH(G26,'Player Board'!$A$5:$A$304,0)),"") -> Available | L26: =IFERROR(INDEX('Player Board'!$E$5:$E$304,MATCH(G26,'Player Board'!$A$5:$A$304,0)),"") | M26: =IF(K26="","NOT ON BOARD",IF(K26="Available","WATCH",IF(L26<>"","SOLD $"&L26,"GONE"))) -> WATCH
A27: TIER 2 | B27: $40–$54 | C27: =COUNTIFS('Player Board'!$R$5:$R$304,">=40",'Player Board'!$R$5:$R$304,"<55",'Player Board'!$D$5:$D$304,"Available") -> 7 | D27: =IF(C27=0,"—",IFERROR(INDEX('Player Board'!$A$5:$A$304,SMALL('Player Board'!$Y$5:$Y$304,1)-4),"")&IF(C27>1,CHAR(10)&IFERROR(INDEX('Player Board'!$A$5:$A$304,SMALL('Player Board'!$Y$5:$Y$304,2)-4),""),"")&IF(C27>2,CHAR(10)&IFERROR(INDEX('Player Board'!$A$5:$A$304,SMALL('Player Board'!$Y$5:$Y$304,3)-4),""),"")) -> Jonathan Taylor CeeDee Lamb Drake London | G27: Wan'Dale Robinson | H27: =IFERROR(INDEX('Player Board'!$G$5:$G$304,MATCH(G27,'Player Board'!$A$5:$A$304,0)),"") -> WR | I27: =IFERROR(INDEX('Player Board'!$S$5:$S$304,MATCH(G27,'Player Board'!$A$5:$A$304,0)),"") -> 8 | J27: =IFERROR(INDEX('Player Board'!$R$5:$R$304,MATCH(G27,'Player Board'!$A$5:$A$304,0)),"") -> 9 | K27: =IFERROR(INDEX('Player Board'!$D$5:$D$304,MATCH(G27,'Player Board'!$A$5:$A$304,0)),"") -> Available | L27: =IFERROR(INDEX('Player Board'!$E$5:$E$304,MATCH(G27,'Player Board'!$A$5:$A$304,0)),"") | M27: =IF(K27="","NOT ON BOARD",IF(K27="Available","WATCH",IF(L27<>"","SOLD $"&L27,"GONE"))) -> WATCH
A28: TIER 3 | B28: $25–$39 | C28: =COUNTIFS('Player Board'!$R$5:$R$304,">=25",'Player Board'!$R$5:$R$304,"<40",'Player Board'!$D$5:$D$304,"Available") -> 27 | D28: =IF(C28=0,"—",IFERROR(INDEX('Player Board'!$A$5:$A$304,SMALL('Player Board'!$Z$5:$Z$304,1)-4),"")&IF(C28>1,CHAR(10)&IFERROR(INDEX('Player Board'!$A$5:$A$304,SMALL('Player Board'!$Z$5:$Z$304,2)-4),""),"")&IF(C28>2,CHAR(10)&IFERROR(INDEX('Player Board'!$A$5:$A$304,SMALL('Player Board'!$Z$5:$Z$304,3)-4),""),"")) -> Chase Brown Chris Olave A.J. Brown | G28: Michael Wilson | H28: =IFERROR(INDEX('Player Board'!$G$5:$G$304,MATCH(G28,'Player Board'!$A$5:$A$304,0)),"") -> WR | I28: =IFERROR(INDEX('Player Board'!$S$5:$S$304,MATCH(G28,'Player Board'!$A$5:$A$304,0)),"") -> 8 | J28: =IFERROR(INDEX('Player Board'!$R$5:$R$304,MATCH(G28,'Player Board'!$A$5:$A$304,0)),"") -> 9 | K28: =IFERROR(INDEX('Player Board'!$D$5:$D$304,MATCH(G28,'Player Board'!$A$5:$A$304,0)),"") -> Available | L28: =IFERROR(INDEX('Player Board'!$E$5:$E$304,MATCH(G28,'Player Board'!$A$5:$A$304,0)),"") | M28: =IF(K28="","NOT ON BOARD",IF(K28="Available","WATCH",IF(L28<>"","SOLD $"&L28,"GONE"))) -> WATCH
G29: Kyle Pitts Sr. | H29: =IFERROR(INDEX('Player Board'!$G$5:$G$304,MATCH(G29,'Player Board'!$A$5:$A$304,0)),"") -> TE | I29: =IFERROR(INDEX('Player Board'!$S$5:$S$304,MATCH(G29,'Player Board'!$A$5:$A$304,0)),"") -> 12 | J29: =IFERROR(INDEX('Player Board'!$R$5:$R$304,MATCH(G29,'Player Board'!$A$5:$A$304,0)),"") -> 14 | K29: =IFERROR(INDEX('Player Board'!$D$5:$D$304,MATCH(G29,'Player Board'!$A$5:$A$304,0)),"") -> Available | L29: =IFERROR(INDEX('Player Board'!$E$5:$E$304,MATCH(G29,'Player Board'!$A$5:$A$304,0)),"") | M29: =IF(K29="","NOT ON BOARD",IF(K29="Available","WATCH",IF(L29<>"","SOLD $"&L29,"GONE"))) -> WATCH
G30: David Montgomery | H30: =IFERROR(INDEX('Player Board'!$G$5:$G$304,MATCH(G30,'Player Board'!$A$5:$A$304,0)),"") -> RB | I30: =IFERROR(INDEX('Player Board'!$S$5:$S$304,MATCH(G30,'Player Board'!$A$5:$A$304,0)),"") -> 13 | J30: =IFERROR(INDEX('Player Board'!$R$5:$R$304,MATCH(G30,'Player Board'!$A$5:$A$304,0)),"") -> 15 | K30: =IFERROR(INDEX('Player Board'!$D$5:$D$304,MATCH(G30,'Player Board'!$A$5:$A$304,0)),"") -> Available | L30: =IFERROR(INDEX('Player Board'!$E$5:$E$304,MATCH(G30,'Player Board'!$A$5:$A$304,0)),"") | M30: =IF(K30="","NOT ON BOARD",IF(K30="Available","WATCH",IF(L30<>"","SOLD $"&L30,"GONE"))) -> WATCH
G31: =IFERROR(INDEX(G26:G30,MATCH("Available",K26:K30,0))&" is still available — current adjusted max $"&MIN($B$10,ROUND(INDEX(J26:J30,MATCH("Available",K26:K30,0))*$B$13,0)),"All listed endgame targets are gone.") -> Matthew Stafford is still available — current adjusted max $10
A33: QUICK ENTRY & RECOVERY — MACRO-FREE
A34: Next entry row | B34: =COUNTIF('Auction Log'!$B$5:$B$304,"<>")+5 -> 5 | D34: ="GO TO AUCTION LOG — enter the next sale in bright-green row "&B34 -> GO TO AUCTION LOG — enter the next sale in bright-green row 5
A35: Undo last sale | B35: =IF(B15=0,"Nothing to undo.","Clear Player, Winner, Price, Roster Slot and Note in Auction Log row "&(B15+4)&".") -> Nothing to undo.
A36: Refresh / reset | B36: Refresh: Ctrl+Alt+F9. Reset: select Auction Log input columns B, D:F and I from row 5 down, then press Delete.

Sheet Player Board
A1: CUSTOM 2026 PLAYER BOARD — VALUE FIRST
A2: LIVE FILTERS: Availability + Position + Signal. Player and Value columns stay frozen while scrolling.
A4: Player | B4: V vs Mkt | C4: Signal | D4: Owner | E4: Sold | F4: Team | G4: Pos | H4: Bye | I4: ECR | J4: Tier | K4: FP Proj | L4: Clay PPR | M4: ESPN 10T $ | N4: 14T Market | O4: Consensus $ | P4: Bonus $ | Q4: Injury $ | R4: Hard Ceiling | S4: Target | T4: Nominate | U4: Injury / News | V4: Sale Value | W4: Pool
A5: Jahmyr Gibbs | B5: =R5-N5 -> 7 | C5: =IF(B5>=5,"SMASH BUY",IF(B5>=2,"BUY",IF(B5>=-1,"NEUTRAL",IF(B5>=-4,"AVOID","DO NOT BID")))) -> SMASH BUY | D5: =IF(COUNTIFS('Auction Log'!$B$5:$B$304,A5,'Auction Log'!$D$5:$D$304,"<>",'Auction Log'!$E$5:$E$304,">0")=0,"Available",IFERROR(INDEX('Auction Log'!$D$5:$D$304,MATCH(1,('Auction Log'!$B$5:$B$304=A5)*('Auction Log'!$D$5:$D$304<>"")*('Auction Log'!$E$5:$E$304>0),0)),"SOLD")) -> Available | E5: =IF(COUNTIFS('Auction Log'!$B$5:$B$304,A5,'Auction Log'!$D$5:$D$304,"<>",'Auction Log'!$E$5:$E$304,">0")=0,"",IFERROR(INDEX('Auction Log'!$E$5:$E$304,MATCH(1,('Auction Log'!$B$5:$B$304=A5)*('Auction Log'!$D$5:$D$304<>"")*('Auction Log'!$E$5:$E$304>0),0)),"")) | F5: DET | G5: RB | H5: 6 | I5: 2 | J5: 1 | K5: 373 | L5: 365 | M5: 57 | N5: 59 | O5: 0 | P5: 3 | Q5: 0 | R5: 66 | S5: 62 | T5: TARGET | V5: =IF(E5="","",R5-E5) | W5: YES | X5: =IF(AND(D5="Available",R5>=55),ROW(),9999) -> 5 | Y5: =IF(AND(D5="Available",R5>=40,R5<55),ROW(),9999) -> 9999 | Z5: =IF(AND(D5="Available",R5>=25,R5<40),ROW(),9999) -> 9999 | AA5: =IF(K5="","",IF(L5="",K5,ROUND(AVERAGE(K5,L5),0))) -> 369
A6: Ja'Marr Chase | B6: =R6-N6 -> 7 | C6: =IF(B6>=5,"SMASH BUY",IF(B6>=2,"BUY",IF(B6>=-1,"NEUTRAL",IF(B6>=-4,"AVOID","DO NOT BID")))) -> SMASH BUY | D6: =IF(COUNTIFS('Auction Log'!$B$5:$B$304,A6,'Auction Log'!$D$5:$D$304,"<>",'Auction Log'!$E$5:$E$304,">0")=0,"Available",IFERROR(INDEX('Auction Log'!$D$5:$D$304,MATCH(1,('Auction Log'!$B$5:$B$304=A6)*('Auction Log'!$D$5:$D$304<>"")*('Auction Log'!$E$5:$E$304>0),0)),"SOLD")) -> Available | E6: =IF(COUNTIFS('Auction Log'!$B$5:$B$304,A6,'Auction Log'!$D$5:$D$304,"<>",'Auction Log'!$E$5:$E$304,">0")=0,"",IFERROR(INDEX('Auction Log'!$E$5:$E$304,MATCH(1,('Auction Log'!$B$5:$B$304=A6)*('Auction Log'!$D$5:$D$304<>"")*('Auction Log'!$E$5:$E$304>0),0)),"")) | F6: CIN | G6: WR | H6: 6 | I6: 1 | J6: 1 | K6: 336 | L6: 337 | M6: 56 | N6: 58 | O6: 0 | P6: 3 | Q6: 0 | R6: 65 | S6: 61 | T6: TARGET | V6: =IF(E6="","",R6-E6) | W6: YES | X6: =IF(AND(D6="Available",R6>=55),ROW(),9999) -> 6 | Y6: =IF(AND(D6="Available",R6>=40,R6<55),ROW(),9999) -> 9999 | Z6: =IF(AND(D6="Available",R6>=25,R6<40),ROW(),9999) -> 9999 | AA6: =IF(K6="","",IF(L6="",K6,ROUND(AVERAGE(K6,L6),0))) -> 337
A7: Bijan Robinson | B7: =R7-N7 -> 7 | C7: =IF(B7>=5,"SMASH BUY",IF(B7>=2,"BUY",IF(B7>=-1,"NEUTRAL",IF(B7>=-4,"AVOID","DO NOT BID")))) -> SMASH BUY | D7: =IF(COUNTIFS('Auction Log'!$B$5:$B$304,A7,'Auction Log'!$D$5:$D$304,"<>",'Auction Log'!$E$5:$E$304,">0")=0,"Available",IFERROR(INDEX('Auction Log'!$D$5:$D$304,MATCH(1,('Auction Log'!$B$5:$B$304=A7)*('Auction Log'!$D$5:$D$304<>"")*('Auction Log'!$E$5:$E$304>0),0)),"SOLD")) -> Available | E7: =IF(COUNTIFS('Auction Log'!$B$5:$B$304,A7,'Auction Log'!$D$5:$D$304,"<>",'Auction Log'!$E$5:$E$304,">0")=0,"",IFERROR(INDEX('Auction Log'!$E$5:$E$304,MATCH(1,('Auction Log'!$B$5:$B$304=A7)*('Auction Log'!$D$5:$D$304<>"")*('Auction Log'!$E$5:$E$304>0),0)),"")) | F7: ATL | G7: RB | H7: 11 | I7: 4 | J7: 1 | K7: 369 | L7: 353 | M7: 56 | N7: 58 | O7: 0 | P7: 3 | Q7: 0 | R7: 65 | S7: 61 | T7: TARGET | V7: =IF(E7="","",R7-E7) | W7: YES | X7: =IF(AND(D7="Available",R7>=55),ROW(),9999) -> 7 | Y7: =IF(AND(D7="Available",R7>=40,R7<55),ROW(),9999) -> 9999 | Z7: =IF(AND(D7="Available",R7>=25,R7<40),ROW(),9999) -> 9999 | AA7: =IF(K7="","",IF(L7="",K7,ROUND(AVERAGE(K7,L7),0))) -> 361
A8: Jaxon Smith-Njigba | B8: =R8-N8 -> 8 | C8: =IF(B8>=5,"SMASH BUY",IF(B8>=2,"BUY",IF(B8>=-1,"NEUTRAL",IF(B8>=-4,"AVOID","DO NOT BID")))) -> SMASH BUY | D8: =IF(COUNTIFS('Auction Log'!$B$5:$B$304,A8,'Auction Log'!$D$5:$D$304,"<>",'Auction Log'!$E$5:$E$304,">0")=0,"Available",IFERROR(INDEX('Auction Log'!$D$5:$D$304,MATCH(1,('Auction Log'!$B$5:$B$304=A8)*('Auction Log'!$D$5:$D$304<>"")*('Auction Log'!$E$5:$E$304>0),0)),"SOLD")) -> Available | E8: =IF(COUNTIFS('Auction Log'!$B$5:$B$304,A8,'Auction Log'!$D$5:$D$304,"<>",'Auction Log'!$E$5:$E$304,">0")=0,"",IFERROR(INDEX('Auction Log'!$E$5:$E$304,MATCH(1,('Auction Log'!$B$5:$B$304=A8)*('Auction Log'!$D$5:$D$304<>"")*('Auction Log'!$E$5:$E$304>0),0)),"")) | F8: SEA | G8: WR | H8: 11 | I8: 5 | J8: 1 | K8: 326 | L8: 327 | M8: 54 | N8: 55 | O8: 0 | P8: 4 | Q8: 0 | R8: 63 | S8: 59 | T8: TARGET | V8: =IF(E8="","",R8-E8) | W8: YES | X8: =IF(AND(D8="Available",R8>=55),ROW(),9999) -> 8 | Y8: =IF(AND(D8="Available",R8>=40,R8<55),ROW(),9999) -> 9999 | Z8: =IF(AND(D8="Available",R8>=25,R8<40),ROW(),9999) -> 9999 | AA8: =IF(K8="","",IF(L8="",K8,ROUND(AVERAGE(K8,L8),0))) -> 327
A9: Puka Nacua | B9: =R9-N9 -> 3 | C9: =IF(B9>=5,"SMASH BUY",IF(B9>=2,"BUY",IF(B9>=-1,"NEUTRAL",IF(B9>=-4,"AVOID","DO NOT BID")))) -> BUY | D9: =IF(COUNTIFS('Auction Log'!$B$5:$B$304,A9,'Auction Log'!$D$5:$D$304,"<>",'Auction Log'!$E$5:$E$304,">0")=0,"Available",IFERROR(INDEX('Auction Log'!$D$5:$D$304,MATCH(1,('Auction Log'!$B$5:$B$304=A9)*('Auction Log'!$D$5:$D$304<>"")*('Auction Log'!$E$5:$E$304>0),0)),"SOLD")) -> Available | E9: =IF(COUNTIFS('Auction Log'!$B$5:$B$304,A9,'Auction Log'!$D$5:$D$304,"<>",'Auction Log'!$E$5:$E$304,">0")=0,"",IFERROR(INDEX('Auction Log'!$E$5:$E$304,MATCH(1,('Auction Log'!$B$5:$B$304=A9)*('Auction Log'!$D$5:$D$304<>"")*('Auction Log'!$E$5:$E$304>0),0)),"")) | F9: LAR | G9: WR | H9: 11 | I9: 3 | J9: 1 | K9: 340 | L9: 356 | M9: 55 | N9: 59 | O9: -1 | P9: 4 | Q9: 4 | R9: 62 | S9: 58 | T9: DRAIN | U9: Groin - still questionable; was not practicing as of 8/24 (ESPN 8/26). Discount only — no smash at full Target. | V9: =IF(E9="","",R9-E9) | W9: YES | X9: =IF(AND(D9="Available",R9>=55),ROW(),9999) -> 9 | Y9: =IF(AND(D9="Available",R9>=40,R9<55),ROW(),9999) -> 9999 | Z9: =IF(AND(D9="Available",R9>=25,R9<40),ROW(),9999) -> 9999 | AA9: =IF(K9="","",IF(L9="",K9,ROUND(AVERAGE(K9,L9),0))) -> 348
A10: Amon-Ra St. Brown | B10: =R10-N10 -> 7 | C10: =IF(B10>=5,"SMASH BUY",IF(B10>=2,"BUY",IF(B10>=-1,"NEUTRAL",IF(B10>=-4,"AVOID","DO NOT BID")))) -> SMASH BUY | D10: =IF(COUNTIFS('Auction Log'!$B$5:$B$304,A10,'Auction Log'!$D$5:$D$304,"<>",'Auction Log'!$E$5:$E$304,">0")=0,"Available",IFERROR(INDEX('Auction Log'!$D$5:$D$304,MATCH(1,('Auction Log'!$B$5:$B$304=A10)*('Auction Log'!$D$5:$D$304<>"")*('Auction Log'!$E$5:$E$304>0),0)),"SOLD")) -> Available | E10: =IF(COUNTIFS('Auction Log'!$B$5:$B$304,A10,'Auction Log'!$D$5:$D$304,"<>",'Auction Log'!$E$5:$E$304,">0")=0,"",IFERROR(INDEX('Auction Log'!$E$5:$E$304,MATCH(1,('Auction Log'!$B$5:$B$304=A10)*('Auction Log'!$D$5:$D$304<>"")*('Auction Log'!$E$5:$E$304>0),0)),"")) | F10: DET | G10: WR | H10: 6 | I10: 6 | J10: 1 | K10: 320 | L10: 324 | M10: 52 | N10: 53 | O10: 0 | P10: 3 | Q10: 0 | R10: 60 | S10: 56 | T10: TARGET | V10: =IF(E10="","",R10-E10) | W10: YES | X10: =IF(AND(D10="Available",R10>=55),ROW(),9999) -> 10 | Y10: =IF(AND(D10="Available",R10>=40,R10<55),ROW(),9999) -> 9999 | Z10: =IF(AND(D10="Available",R10>=25,R10<40),ROW(),9999) -> 9999 | AA10: =IF(K10="","",IF(L10="",K10,ROUND(AVERAGE(K10,L10),0))) -> 322
A11: Christian McCaffrey | B11: =R11-N11 -> 7 | C11: =IF(B11>=5,"SMASH BUY",IF(B11>=2,"BUY",IF(B11>=-1,"NEUTRAL",IF(B11>=-4,"AVOID","DO NOT BID")))) -> SMASH BUY | D11: =IF(COUNTIFS('Auction Log'!$B$5:$B$304,A11,'Auction Log'!$D$5:$D$304,"<>",'Auction Log'!$E$5:$E$304,">0")=0,"Available",IFERROR(INDEX('Auction Log'!$D$5:$D$304,MATCH(1,('Auction Log'!$B$5:$B$304=A11)*('Auction Log'!$D$5:$D$304<>"")*('Auction Log'!$E$5:$E$304>0),0)),"SOLD")) -> Available | E11: =IF(COUNTIFS('Auction Log'!$B$5:$B$304,A11,'Auction Log'!$D$5:$D$304,"<>",'Auction Log'!$E$5:$E$304,">0")=0,"",IFERROR(INDEX('Auction Log'!$E$5:$E$304,MATCH(1,('Auction Log'!$B$5:$B$304=A11)*('Auction Log'!$D$5:$D$304<>"")*('Auction Log'!$E$5:$E$304>0),0)),"")) | F11: SF | G11: RB | H11: 8 | I11: 9 | J11: 2 | K11: 335 | L11: 343 | M11: 53 | N11: 49 | O11: 1 | P11: 2 | Q11: 0 | R11: 56 | S11: 52 | T11: TARGET | V11: =IF(E11="","",R11-E11) | W11: YES | X11: =IF(AND(D11="Available",R11>=55),ROW(),9999) -> 11 | Y11: =IF(AND(D11="Available",R11>=40,R11<55),ROW(),9999) -> 9999 | Z11: =IF(AND(D11="Available",R11>=25,R11<40),ROW(),9999) -> 9999 | AA11: =IF(K11="","",IF(L11="",K11,ROUND(AVERAGE(K11,L11),0))) -> 339
A12: Jonathan Taylor | B12: =R12-N12 -> 8 | C12: =IF(B12>=5,"SMASH BUY",IF(B12>=2,"BUY",IF(B12>=-1,"NEUTRAL",IF(B12>=-4,"AVOID","DO NOT BID")))) -> SMASH BUY | D12: =IF(COUNTIFS('Auction Log'!$B$5:$B$304,A12,'Auction Log'!$D$5:$D$304,"<>",'Auction Log'!$E$5:$E$304,">0")=0,"Available",IFERROR(INDEX('Auction Log'!$D$5:$D$304,MATCH(1,('Auction Log'!$B$5:$B$304=A12)*('Auction Log'!$D$5:$D$304<>"")*('Auction Log'!$E$5:$E$304>0),0)),"SOLD")) -> Available | E12: =IF(COUNTIFS('Auction Log'!$B$5:$B$304,A12,'Auction Log'!$D$5:$D$304,"<>",'Auction Log'!$E$5:$E$304,">0")=0,"",IFERROR(INDEX('Auction Log'!$E$5:$E$304,MATCH(1,('Auction Log'!$B$5:$B$304=A12)*('Auction Log'!$D$5:$D$304<>"")*('Auction Log'!$E$5:$E$304>0),0)),"")) | F12: IND | G12: RB | H12: 13 | I12: 10 | J12: 2 | K12: 310 | L12: 316 | M12: 52 | N12: 43 | O12: 2 | P12: 3 | Q12: 0 | R12: 51 | S12: 47 | T12: TARGET | V12: =IF(E12="","",R12-E12) | W12: YES | X12: =IF(AND(D12="Available",R12>=55),ROW(),9999) -> 9999 | Y12: =IF(AND(D12="Available",R12>=40,R12<55),ROW(),9999) -> 12 | Z12: =IF(AND(D12="Available",R12>=25,R12<40),ROW(),9999) -> 9999 | AA12: =IF(K12="","",IF(L12="",K12,ROUND(AVERAGE(K12,L12),0))) -> 313
A13: CeeDee Lamb | B13: =R13-N13 -> 9 | C13: =IF(B13>=5,"SMASH BUY",IF(B13>=2,"BUY",IF(B13>=-1,"NEUTRAL",IF(B13>=-4,"AVOID","DO NOT BID")))) -> SMASH BUY | D13: =IF(COUNTIFS('Auction Log'!$B$5:$B$304,A13,'Auction Log'!$D$5:$D$304,"<>",'Auction Log'!$E$5:$E$304,">0")=0,"Available",IFERROR(INDEX('Auction Log'!$D$5:$D$304,MATCH(1,('Auction Log'!$B$5:$B$304=A13)*('Auction Log'!$D$5:$D$304<>"")*('Auction Log'!$E$5:$E$304>0),0)),"SOLD")) -> Available | E13: =IF(COUNTIFS('Auction Log'!$B$5:$B$304,A13,'Auction Log'!$D$5:$D$304,"<>",'Auction Log'!$E$5:$E$304,">0")=0,"",IFERROR(INDEX('Auction Log'!$E$5:$E$304,MATCH(1,('Auction Log'!$B$5:$B$304=A13)*('Auction Log'!$D$5:$D$304<>"")*('Auction Log'!$E$5:$E$304>0),0)),"")) | F13: DAL | G13: WR | H13: 14 | I13: 7 | J13: 2 | K13: 273 | L13: 293 | M13: 51 | N13: 39 | O13: 3 | P13: 3 | Q13: 0 | R13: 48 | S13: 44 | T13: TARGET | V13: =IF(E13="","",R13-E13) | W13: YES | X13: =IF(AND(D13="Available",R13>=55),ROW(),9999) -> 9999 | Y13: =IF(AND(D13="Available",R13>=40,R13<55),ROW(),9999) -> 13 | Z13: =IF(AND(D13="Available",R13>=25,R13<40),ROW(),9999) -> 9999 | AA13: =IF(K13="","",IF(L13="",K13,ROUND(AVERAGE(K13,L13),0))) -> 283
A14: Drake London | B14: =R14-N14 -> 5 | C14: =IF(B14>=5,"SMASH BUY",IF(B14>=2,"BUY",IF(B14>=-1,"NEUTRAL",IF(B14>=-4,"AVOID","DO NOT BID")))) -> SMASH BUY | D14: =IF(COUNTIFS('Auction Log'!$B$5:$B$304,A14,'Auction Log'!$D$5:$D$304,"<>",'Auction Log'!$E$5:$E$304,">0")=0,"Available",IFERROR(INDEX('Auction Log'!$D$5:$D$304,MATCH(1,('Auction Log'!$B$5:$B$304=A14)*('Auction Log'!$D$5:$D$304<>"")*('Auction Log'!$E$5:$E$304>0),0)),"SOLD")) -> Available | E14: =IF(COUNTIFS('Auction Log'!$B$5:$B$304,A14,'Auction Log'!$D$5:$D$304,"<>",'Auction Log'!$E$5:$E$304,">0")=0,"",IFERROR(INDEX('Auction Log'!$E$5:$E$304,MATCH(1,('Auction Log'!$B$5:$B$304=A14)*('Auction Log'!$D$5:$D$304<>"")*('Auction Log'!$E$5:$E$304>0),0)),"")) | F14: ATL | G14: WR | H14: 11 | I14: 11 | J14: 2 | K14: 287 | L14: 270 | M14: 43 | N14: 43 | O14: 0 | P14: 2 | Q14: 0 | R14: 48 | S14: 44 | T14: TARGET | V14: =IF(E14="","",R14-E14) | W14: YES | X14: =IF(AND(D14="Available",R14>=55),ROW(),9999) -> 9999 | Y14: =IF(AND(D14="Available",R14>=40,R14<55),ROW(),9999) -> 14 | Z14: =IF(AND(D14="Available",R14>=25,R14<40),ROW(),9999) -> 9999 | AA14: =IF(K14="","",IF(L14="",K14,ROUND(AVERAGE(K14,L14),0))) -> 279
A15: Justin Jefferson | B15: =R15-N15 -> 7 | C15: =IF(B15>=5,"SMASH BUY",IF(B15>=2,"BUY",IF(B15>=-1,"NEUTRAL",IF(B15>=-4,"AVOID","DO NOT BID")))) -> SMASH BUY | D15: =IF(COUNTIFS('Auction Log'!$B$5:$B$304,A15,'Auction Log'!$D$5:$D$304,"<>",'Auction Log'!$E$5:$E$304,">0")=0,"Available",IFERROR(INDEX('Auction Log'!$D$5:$D$304,MATCH(1,('Auction Log'!$B$5:$B$304=A15)*('Auction Log'!$D$5:$D$304<>"")*('Auction Log'!$E$5:$E$304>0),0)),"SOLD")) -> Available | E15: =IF(COUNTIFS('Auction Log'!$B$5:$B$304,A15,'Auction Log'!$D$5:$D$304,"<>",'Auction Log'!$E$5:$E$304,">0")=0,"",IFERROR(INDEX('Auction Log'!$E$5:$E$304,MATCH(1,('Auction Log'!$B$5:$B$304=A15)*('Auction Log'!$D$5:$D$304<>"")*('Auction Log'!$E$5:$E$304>0),0)),"")) | F15: MIN | G15: WR | H15: 6 | I15: 8 | J15: 2 | K15: 272 | L15: 294 | M15: 48 | N15: 39 | O15: 2 | P15: 2 | Q15: 0 | R15: 46 | S15: 42 | T15: TARGET | V15: =IF(E15="","",R15-E15) | W15: YES | X15: =IF(AND(D15="Available",R15>=55),ROW(),9999) -> 9999 | Y15: =IF(AND(D15="Available",R15>=40,R15<55),ROW(),9999) -> 15 | Z15: =IF(AND(D15="Available",R15>=25,R15<40),ROW(),9999) -> 9999 | AA15: =IF(K15="","",IF(L15="",K15,ROUND(AVERAGE(K15,L15),0))) -> 283
A16: De'Von Achane | B16: =R16-N16 -> 6 | C16: =IF(B16>=5,"SMASH BUY",IF(B16>=2,"BUY",IF(B16>=-1,"NEUTRAL",IF(B16>=-4,"AVOID","DO NOT BID")))) -> SMASH BUY | D16: =IF(COUNTIFS('Auction Log'!$B$5:$B$304,A16,'Auction Log'!$D$5:$D$304,"<>",'Auction Log'!$E$5:$E$304,">0")=0,"Available",IFERROR(INDEX('Auction Log'!$D$5:$D$304,MATCH(1,('Auction Log'!$B$5:$B$304=A16)*('Auction Log'!$D$5:$D$304<>"")*('Auction Log'!$E$5:$E$304>0),0)),"SOLD")) -> Available | E16: =IF(COUNTIFS('Auction Log'!$B$5:$B$304,A16,'Auction Log'!$D$5:$D$304,"<>",'Auction Log'!$E$5:$E$304,">0")=0,"",IFERROR(INDEX('Auction Log'!$E$5:$E$304,MATCH(1,('Auction Log'!$B$5:$B$304=A16)*('Auction Log'!$D$5:$D$304<>"")*('Auction Log'!$E$5:$E$304>0),0)),"")) | F16: MIA | G16: RB | H16: 6 | I16: 19 | J16: 3 | K16: 292 | L16: 293 | M16: 50 | N16: 39 | O16: 1 | P16: 2 | Q16: 0 | R16: 45 | S16: 41 | T16: TARGET | V16: =IF(E16="","",R16-E16) | W16: YES | X16: =IF(AND(D16="Available",R16>=55),ROW(),9999) -> 9999 | Y16: =IF(AND(D16="Available",R16>=40,R16<55),ROW(),9999) -> 16 | Z16: =IF(AND(D16="Available",R16>=25,R16<40),ROW(),9999) -> 9999 | AA16: =IF(K16="","",IF(L16="",K16,ROUND(AVERAGE(K16,L16),0))) -> 293
A17: James Cook III | B17: =R17-N17 -> 8 | C17: =IF(B17>=5,"SMASH BUY",IF(B17>=2,"BUY",IF(B17>=-1,"NEUTRAL",IF(B17>=-4,"AVOID","DO NOT BID")))) -> SMASH BUY | D17: =IF(COUNTIFS('Auction Log'!$B$5:$B$304,A17,'Auction Log'!$D$5:$D$304,"<>",'Auction Log'!$E$5:$E$304,">0")=0,"Available",IFERROR(INDEX('Auction Log'!$D$5:$D$304,MATCH(1,('Auction Log'!$B$5:$B$304=A17)*('Auction Log'!$D$5:$D$304<>"")*('Auction Log'!$E$5:$E$304>0),0)),"SOLD")) -> Available | E17: =IF(COUNTIFS('Auction Log'!$B$5:$B$304,A17,'Auction Log'!$D$5:$D$304,"<>",'Auction Log'!$E$5:$E$304,">0")=0,"",IFERROR(INDEX('Auction Log'!$E$5:$E$304,MATCH(1,('Auction Log'!$B$5:$B$304=A17)*('Auction Log'!$D$5:$D$304<>"")*('Auction Log'!$E$5:$E$304>0),0)),"")) | F17: BUF | G17: RB | H17: 7 | I17: 14 | J17: 3 | K17: 271 | L17: 280 | M17: 46 | N17: 34 | O17: 3 | P17: 3 | Q17: 0 | R17: 42 | S17: 39 | T17: TARGET | V17: =IF(E17="","",R17-E17) | W17: YES | X17: =IF(AND(D17="Available",R17>=55),ROW(),9999) -> 9999 | Y17: =IF(AND(D17="Available",R17>=40,R17<55),ROW(),9999) -> 17 | Z17: =IF(AND(D17="Available",R17>=25,R17<40),ROW(),9999) -> 9999 | AA17: =IF(K17="","",IF(L17="",K17,ROUND(AVERAGE(K17,L17),0))) -> 276
A18: Rashee Rice | B18: =R18-N18 -> 2 | C18: =IF(B18>=5,"SMASH BUY",IF(B18>=2,"BUY",IF(B18>=-1,"NEUTRAL",IF(B18>=-4,"AVOID","DO NOT BID")))) -> BUY | D18: =IF(COUNTIFS('Auction Log'!$B$5:$B$304,A18,'Auction Log'!$D$5:$D$304,"<>",'Auction Log'!$E$5:$E$304,">0")=0,"Available",IFERROR(INDEX('Auction Log'!$D$5:$D$304,MATCH(1,('Auction Log'!$B$5:$B$304=A18)*('Auction Log'!$D$5:$D$304<>"")*('Auction Log'!$E$5:$E$304>0),0)),"SOLD")) -> Available | E18: =IF(COUNTIFS('Auction Log'!$B$5:$B$304,A18,'Auction Log'!$D$5:$D$304,"<>",'Auction Log'!$E$5:$E$304,">0")=0,"",IFERROR(INDEX('Auction Log'!$E$5:$E$304,MATCH(1,('Auction Log'!$B$5:$B$304=A18)*('Auction Log'!$D$5:$D$304<>"")*('Auction Log'!$E$5:$E$304>0),0)),"")) | F18: KC | G18: WR | H18: 5 | I18: 21 | J18: 3 | K18: 274 | L18: 271 | M18: 40 | N18: 40 | O18: -1 | P18: 1 | Q18: 0 | R18: 42 | S18: 39 | T18: HOLD | V18: =IF(E18="","",R18-E18) | W18: YES | X18: =IF(AND(D18="Available",R18>=55),ROW(),9999) -> 9999 | Y18: =IF(AND(D18="Available",R18>=40,R18<55),ROW(),9999) -> 18 | Z18: =IF(AND(D18="Available",R18>=25,R18<40),ROW(),9999) -> 9999 | AA18: =IF(K18="","",IF(L18="",K18,ROUND(AVERAGE(K18,L18),0))) -> 273
A19: Chase Brown | B19: =R19-N19 -> 3 | C19: =IF(B19>=5,"SMASH BUY",IF(B19>=2,"BUY",IF(B19>=-1,"NEUTRAL",IF(B19>=-4,"AVOID","DO NOT BID")))) -> BUY | D19: =IF(COUNTIFS('Auction Log'!$B$5:$B$304,A19,'Auction Log'!$D$5:$D$304,"<>",'Auction Log'!$E$5:$E$304,">0")=0,"Available",IFERROR(INDEX('Auction Log'!$D$5:$D$304,MATCH(1,('Auction Log'!$B$5:$B$304=A19)*('Auction Log'!$D$5:$D$304<>"")*('Auction Log'!$E$5:$E$304>0),0)),"SOLD")) -> Available | E19: =IF(COUNTIFS('Auction Log'!$B$5:$B$304,A19,'Auction Log'!$D$5:$D$304,"<>",'Auction Log'!$E$5:$E$304,">0")=0,"",IFERROR(INDEX('Auction Log'!$E$5:$E$304,MATCH(1,('Auction Log'!$B$5:$B$304=A19)*('Auction Log'!$D$5:$D$304<>"")*('Auction Log'!$E$5:$E$304>0),0)),"")) | F19: CIN | G19: RB | H19: 6 | I19: 15 | J19: 3 | K19: 279 | L19: 272 | M19: 35 | N19: 36 | O19: 0 | P19: 1 | Q19: 0 | R19: 39 | S19: 36 | T19: HOLD | V19: =IF(E19="","",R19-E19) | W19: YES | X19: =IF(AND(D19="Available",R19>=55),ROW(),9999) -> 9999 | Y19: =IF(AND(D19="Available",R19>=40,R19<55),ROW(),9999) -> 9999 | Z19: =IF(AND(D19="Available",R19>=25,R19<40),ROW(),9999) -> 19 | AA19: =IF(K19="","",IF(L19="",K19,ROUND(AVERAGE(K19,L19),0))) -> 276
A20: Chris Olave | B20: =R20-N20 -> 3 | C20: =IF(B20>=5,"SMASH BUY",IF(B20>=2,"BUY",IF(B20>=-1,"NEUTRAL",IF(B20>=-4,"AVOID","DO NOT BID")))) -> BUY | D20: =IF(COUNTIFS('Auction Log'!$B$5:$B$304,A20,'Auction Log'!$D$5:$D$304,"<>",'Auction Log'!$E$5:$E$304,">0")=0,"Available",IFERROR(INDEX('Auction Log'!$D$5:$D$304,MATCH(1,('Auction Log'!$B$5:$B$304=A20)*('Auction Log'!$D$5:$D$304<>"")*('Auction Log'!$E$5:$E$304>0),0)),"SOLD")) -> Available | E20: =IF(COUNTIFS('Auction Log'!$B$5:$B$304,A20,'Auction Log'!$D$5:$D$304,"<>",'Auction Log'!$E$5:$E$304,">0")=0,"",IFERROR(INDEX('Auction Log'!$E$5:$E$304,MATCH(1,('Auction Log'!$B$5:$B$304=A20)*('Auction Log'!$D$5:$D$304<>"")*('Auction Log'!$E$5:$E$304>0),0)),"")) | F20: NO | G20: WR | H20: 8 | I20: 17 | J20: 3 | K20: 262 | L20: 250 | M20: 30 | N20: 36 | O20: -1 | P20: 2 | Q20: 0 | R20: 39 | S20: 36 | T20: HOLD | V20: =IF(E20="","",R20-E20) | W20: YES | X20: =IF(AND(D20="Available",R20>=55),ROW(),9999) -> 9999 | Y20: =IF(AND(D20="Available",R20>=40,R20<55),ROW(),9999) -> 9999 | Z20: =IF(AND(D20="Available",R20>=25,R20<40),ROW(),9999) -> 20 | AA20: =IF(K20="","",IF(L20="",K20,ROUND(AVERAGE(K20,L20),0))) -> 256
A21: A.J. Brown | B21: =R21-N21 -> 3 | C21: =IF(B21>=5,"SMASH BUY",IF(B21>=2,"BUY",IF(B21>=-1,"NEUTRAL",IF(B21>=-4,"AVOID","DO NOT BID")))) -> BUY | D21: =IF(COUNTIFS('Auction Log'!$B$5:$B$304,A21,'Auction Log'!$D$5:$D$304,"<>",'Auction Log'!$E$5:$E$304,">0")=0,"Available",IFERROR(INDEX('Auction Log'!$D$5:$D$304,MATCH(1,('Auction Log'!$B$5:$B$304=A21)*('Auction Log'!$D$5:$D$304<>"")*('Auction Log'!$E$5:$E$304>0),0)),"SOLD")) -> Available | E21: =IF(COUNTIFS('Auction Log'!$B$5:$B$304,A21,'Auction Log'!$D$5:$D$304,"<>",'Auction Log'!$E$5:$E$304,">0")=0,"",IFERROR(INDEX('Auction Log'!$E$5:$E$304,MATCH(1,('Auction Log'!$B$5:$B$304=A21)*('Auction Log'!$D$5:$D$304<>"")*('Auction Log'!$E$5:$E$304>0),0)),"")) | F21: NE | G21: WR | H21: 11 | I21: 12 | J21: 3 | K21: 256 | L21: 249 | M21: 29 | N21: 35 | O21: -1 | P21: 2 | Q21: 0 | R21: 38 | S21: 35 | T21: HOLD | V21: =IF(E21="","",R21-E21) | W21: YES | X21: =IF(AND(D21="Available",R21>=55),ROW(),9999) -> 9999 | Y21: =IF(AND(D21="Available",R21>=40,R21<55),ROW(),9999) -> 9999 | Z21: =IF(AND(D21="Available",R21>=25,R21<40),ROW(),9999) -> 21 | AA21: =IF(K21="","",IF(L21="",K21,ROUND(AVERAGE(K21,L21),0))) -> 253
... A29: Omarion Hampton | B29: =R29-N29 -> 4 | C29: =IF(B29>=5,"SMASH BUY",IF(B29>=2,"BUY",IF(B29>=-1,"NEUTRAL",IF(B29>=-4,"AVOID","DO NOT BID")))) -> BUY | D29: =IF(COUNTIFS('Auction Log'!$B$5:$B$304,A29,'Auction Log'!$D$5:$D$304,"<>",'Auction Log'!$E$5:$E$304,">0")=0,"Available",IFERROR(INDEX('Auction Log'!$D$5:$D$304,MATCH(1,('Auction Log'!$B$5:$B$304=A29)*('Auction Log'!$D$5:$D$304<>"")*('Auction Log'!$E$5:$E$304>0),0)),"SOLD")) -> Available | E29: =IF(COUNTIFS('Auction Log'!$B$5:$B$304,A29,'Auction Log'!$D$5:$D$304,"<>",'Auction Log'!$E$5:$E$304,">0")=0,"",IFERROR(INDEX('Auction Log'!$E$5:$E$304,MATCH(1,('Auction Log'!$B$5:$B$304=A29)*('Auction Log'!$D$5:$D$304<>"")*('Auction Log'!$E$5:$E$304>0),0)),"")) | F29: LAC | G29: RB | H29: 7 | I29: 25 | J29: 4 | K29: 254 | L29: 262 | M29: 33 | N29: 30 | O29: 1 | P29: 1 | Q29: 0 | R29: 34 | S29: 31 | T29: TARGET | V29: =IF(E29="","",R29-E29) | W29: YES | X29: =IF(AND(D29="Available",R29>=55),ROW(),9999) -> 9999 | Y29: =IF(AND(D29="Available",R29>=40,R29<55),ROW(),9999) -> 9999 | Z29: =IF(AND(D29="Available",R29>=25,R29<40),ROW(),9999) -> 29 | AA29: =IF(K29="","",IF(L29="",K29,ROUND(AVERAGE(K29,L29),0))) -> 258
A30: Ashton Jeanty | B30: =R30-N30 -> 2 | C30: =IF(B30>=5,"SMASH BUY",IF(B30>=2,"BUY",IF(B30>=-1,"NEUTRAL",IF(B30>=-4,"AVOID","DO NOT BID")))) -> BUY | D30: =IF(COUNTIFS('Auction Log'!$B$5:$B$304,A30,'Auction Log'!$D$5:$D$304,"<>",'Auction Log'!$E$5:$E$304,">0")=0,"Available",IFERROR(INDEX('Auction Log'!$D$5:$D$304,MATCH(1,('Auction Log'!$B$5:$B$304=A30)*('Auction Log'!$D$5:$D$304<>"")*('Auction Log'!$E$5:$E$304>0),0)),"SOLD")) -> Available | E30: =IF(COUNTIFS('Auction Log'!$B$5:$B$304,A30,'Auction Log'!$D$5:$D$304,"<>",'Auction Log'!$E$5:$E$304,">0")=0,"",IFERROR(INDEX('Auction Log'!$E$5:$E$304,MATCH(1,('Auction Log'!$B$5:$B$304=A30)*('Auction Log'!$D$5:$D$304<>"")*('Auction Log'!$E$5:$E$304>0),0)),"")) | F30: LV | G30: RB | H30: 13 | I30: 28 | J30: 4 | K30: 261 | L30: 281 | M30: 45 | N30: 32 | O30: 3 | P30: 1 | Q30: 4 | R30: 34 | S30: 31 | T30: DRAIN | U30: Ankle - Raiders optimistic 'more low than high' sprain, not long-term (Rapoport 8/25 via ESPN). Buyable near Target; not a healthy stud. | V30: =IF(E30="","",R30-E30) | W30: YES | X30: =IF(AND(D30="Available",R30>=55),ROW(),9999) -> 9999 | Y30: =IF(AND(D30="Available",R30>=40,R30<55),ROW(),9999) -> 9999 | Z30: =IF(AND(D30="Available",R30>=25,R30<40),ROW(),9999) -> 30 | AA30: =IF(K30="","",IF(L30="",K30,ROUND(AVERAGE(K30,L30),0))) -> 271
A31: Garrett Wilson | B31: =R31-N31 -> 3 | C31: =IF(B31>=5,"SMASH BUY",IF(B31>=2,"BUY",IF(B31>=-1,"NEUTRAL",IF(B31>=-4,"AVOID","DO NOT BID")))) -> BUY | D31: =IF(COUNTIFS('Auction Log'!$B$5:$B$304,A31,'Auction Log'!$D$5:$D$304,"<>",'Auction Log'!$E$5:$E$304,">0")=0,"Available",IFERROR(INDEX('Auction Log'!$D$5:$D$304,MATCH(1,('Auction Log'!$B$5:$B$304=A31)*('Auction Log'!$D$5:$D$304<>"")*('Auction Log'!$E$5:$E$304>0),0)),"SOLD")) -> Available | E31: =IF(COUNTIFS('Auction Log'!$B$5:$B$304,A31,'Auction Log'!$D$5:$D$304,"<>",'Auction Log'!$E$5:$E$304,">0")=0,"",IFERROR(INDEX('Auction Log'!$E$5:$E$304,MATCH(1,('Auction Log'!$B$5:$B$304=A31)*('Auction Log'!$D$5:$D$304<>"")*('Auction Log'!$E$5:$E$304>0),0)),"")) | F31: NYJ | G31: WR | H31: 13 | I31: 29 | J31: 4 | K31: 243 | L31: 250 | M31: 30 | N31: 31 | O31: 0 | P31: 1 | Q31: 0 | R31: 34 | S31: 31 | T31: HOLD | V31: =IF(E31="","",R31-E31) | W31: YES | X31: =IF(AND(D31="Available",R31>=55),ROW(),9999) -> 9999 | Y31: =IF(AND(D31="Available",R31>=40,R31<55),ROW(),9999) -> 9999 | Z31: =IF(AND(D31="Available",R31>=25,R31<40),ROW(),9999) -> 31 | AA31: =IF(K31="","",IF(L31="",K31,ROUND(AVERAGE(K31,L31),0))) -> 247
A32: Malik Nabers | B32: =R32-N32 -> 2 | C32: =IF(B32>=5,"SMASH BUY",IF(B32>=2,"BUY",IF(B32>=-1,"NEUTRAL",IF(B32>=-4,"AVOID","DO NOT BID")))) -> BUY | D32: =IF(COUNTIFS('Auction Log'!$B$5:$B$304,A32,'Auction Log'!$D$5:$D$304,"<>",'Auction Log'!$E$5:$E$304,">0")=0,"Available",IFERROR(INDEX('Auction Log'!$D$5:$D$304,MATCH(1,('Auction Log'!$B$5:$B$304=A32)*('Auction Log'!$D$5:$D$304<>"")*('Auction Log'!$E$5:$E$304>0),0)),"SOLD")) -> Available | E32: =IF(COUNTIFS('Auction Log'!$B$5:$B$304,A32,'Auction Log'!$D$5:$D$304,"<>",'Auction Log'!$E$5:$E$304,">0")=0,"",IFERROR(INDEX('Auction Log'!$E$5:$E$304,MATCH(1,('Auction Log'!$B$5:$B$304=A32)*('Auction Log'!$D$5:$D$304<>"")*('Auction Log'!$E$5:$E$304>0),0)),"")) | F32: NYG | G32: WR | H32: 8 | I32: 24 | J32: 4 | K32: 240 | L32: 246 | M32: 28 | N32: 30 | O32: 0 | P32: 1 | Q32: 1 | R32: 32 | S32: 29 | T32: HOLD | U32: Knee - still on limited/red-jersey path as of 8/23 (ESPN). Cap at Target; do not chase. | V32: =IF(E32="","",R32-E32) | W32: YES | X32: =IF(AND(D32="Available",R32>=55),ROW(),9999) -> 9999 | Y32: =IF(AND(D32="Available",R32>=40,R32<55),ROW(),9999) -> 9999 | Z32: =IF(AND(D32="Available",R32>=25,R32<40),ROW(),9999) -> 32 | AA32: =IF(K32="","",IF(L32="",K32,ROUND(AVERAGE(K32,L32),0))) -> 243
A33: Zay Flowers | B33: =R33-N33 -> 2 | C33: =IF(B33>=5,"SMASH BUY",IF(B33>=2,"BUY",IF(B33>=-1,"NEUTRAL",IF(B33>=-4,"AVOID","DO NOT BID")))) -> BUY | D33: =IF(COUNTIFS('Auction Log'!$B$5:$B$304,A33,'Auction Log'!$D$5:$D$304,"<>",'Auction Log'!$E$5:$E$304,">0")=0,"Available",IFERROR(INDEX('Auction Log'!$D$5:$D$304,MATCH(1,('Auction Log'!$B$5:$B$304=A33)*('Auction Log'!$D$5:$D$304<>"")*('Auction Log'!$E$5:$E$304>0),0)),"SOLD")) -> Available | E33: =IF(COUNTIFS('Auction Log'!$B$5:$B$304,A33,'Auction Log'!$D$5:$D$304,"<>",'Auction Log'!$E$5:$E$304,">0")=0,"",IFERROR(INDEX('Auction Log'!$E$5:$E$304,MATCH(1,('Auction Log'!$B$5:$B$304=A33)*('Auction Log'!$D$5:$D$304<>"")*('Auction Log'!$E$5:$E$304>0),0)),"")) | F33: BAL | G33: WR | H33: 13 | I33: 30 | J33: 4 | K33: 242 | L33: 239 | M33: 23 | N33: 30 | O33: -2 | P33: 2 | Q33: 0 | R33: 32 | S33: 29 | T33: HOLD | V33: =IF(E33="","",R33-E33) | W33: YES | X33: =IF(AND(D33="Available",R33>=55),ROW(),9999) -> 9999 | Y33: =IF(AND(D33="Available",R33>=40,R33<55),ROW(),9999) -> 9999 | Z33: =IF(AND(D33="Available",R33>=25,R33<40),ROW(),9999) -> 33 | AA33: =IF(K33="","",IF(L33="",K33,ROUND(AVERAGE(K33,L33),0))) -> 241
A34: DeVonta Smith | B34: =R34-N34 -> 1 | C34: =IF(B34>=5,"SMASH BUY",IF(B34>=2,"BUY",IF(B34>=-1,"NEUTRAL",IF(B34>=-4,"AVOID","DO NOT BID")))) -> NEUTRAL | D34: =IF(COUNTIFS('Auction Log'!$B$5:$B$304,A34,'Auction Log'!$D$5:$D$304,"<>",'Auction Log'!$E$5:$E$304,">0")=0,"Available",IFERROR(INDEX('Auction Log'!$D$5:$D$304,MATCH(1,('Auction Log'!$B$5:$B$304=A34)*('Auction Log'!$D$5:$D$304<>"")*('Auction Log'!$E$5:$E$304>0),0)),"SOLD")) -> Available | E34: =IF(COUNTIFS('Auction Log'!$B$5:$B$304,A34,'Auction Log'!$D$5:$D$304,"<>",'Auction Log'!$E$5:$E$304,">0")=0,"",IFERROR(INDEX('Auction Log'!$E$5:$E$304,MATCH(1,('Auction Log'!$B$5:$B$304=A34)*('Auction Log'!$D$5:$D$304<>"")*('Auction Log'!$E$5:$E$304>0),0)),"")) | F34: PHI | G34: WR | H34: 10 | I34: 22 | J34: 4 | K34: 237 | L34: 239 | M34: 22 | N34: 29 | O34: -1 | P34: 1 | Q34: 0 | R34: 30 | S34: 27 | T34: TARGET | V34: =IF(E34="","",R34-E34) | W34: YES | X34: =IF(AND(D34="Available",R34>=55),ROW(),9999) -> 9999 | Y34: =IF(AND(D34="Available",R34>=40,R34<55),ROW(),9999) -> 9999 | Z34: =IF(AND(D34="Available",R34>=25,R34<40),ROW(),9999) -> 34 | AA34: =IF(K34="","",IF(L34="",K34,ROUND(AVERAGE(K34,L34),0))) -> 238
A35: Josh Allen | B35: =R35-N35 -> 0 | C35: =IF(B35>=5,"SMASH BUY",IF(B35>=2,"BUY",IF(B35>=-1,"NEUTRAL",IF(B35>=-4,"AVOID","DO NOT BID")))) -> NEUTRAL | D35: =IF(COUNTIFS('Auction Log'!$B$5:$B$304,A35,'Auction Log'!$D$5:$D$304,"<>",'Auction Log'!$E$5:$E$304,">0")=0,"Available",IFERROR(INDEX('Auction Log'!$D$5:$D$304,MATCH(1,('Auction Log'!$B$5:$B$304=A35)*('Auction Log'!$D$5:$D$304<>"")*('Auction Log'!$E$5:$E$304>0),0)),"SOLD")) -> Available | E35: =IF(COUNTIFS('Auction Log'!$B$5:$B$304,A35,'Auction Log'!$D$5:$D$304,"<>",'Auction Log'!$E$5:$E$304,">0")=0,"",IFERROR(INDEX('Auction Log'!$E$5:$E$304,MATCH(1,('Auction Log'!$B$5:$B$304=A35)*('Auction Log'!$D$5:$D$304<>"")*('Auction Log'!$E$5:$E$304>0),0)),"")) | F35: BUF | G35: QB | H35: 7 | I35: 26 | J35: 4 | K35: 372 | L35: 369 | M35: 22 | N35: 30 | O35: -2 | P35: 1 | Q35: 0 | R35: 30 | S35: 27 | T35: HOLD | V35: =IF(E35="","",R35-E35) | W35: YES | X35: =IF(AND(D35="Available",R35>=55),ROW(),9999) -> 9999 | Y35: =IF(AND(D35="Available",R35>=40,R35<55),ROW(),9999) -> 9999 | Z35: =IF(AND(D35="Available",R35>=25,R35<40),ROW(),9999) -> 35 | AA35: =IF(K35="","",IF(L35="",K35,ROUND(AVERAGE(K35,L35),0))) -> 371
A36: Tetairoa McMillan | B36: =R36-N36 -> 2 | C36: =IF(B36>=5,"SMASH BUY",IF(B36>=2,"BUY",IF(B36>=-1,"NEUTRAL",IF(B36>=-4,"AVOID","DO NOT BID")))) -> BUY | D36: =IF(COUNTIFS('Auction Log'!$B$5:$B$304,A36,'Auction Log'!$D$5:$D$304,"<>",'Auction Log'!$E$5:$E$304,">0")=0,"Available",IFERROR(INDEX('Auction Log'!$D$5:$D$304,MATCH(1,('Auction Log'!$B$5:$B$304=A36)*('Auction Log'!$D$5:$D$304<>"")*('Auction Log'!$E$5:$E$304>0),0)),"SOLD")) -> Available | E36: =IF(COUNTIFS('Auction Log'!$B$5:$B$304,A36,'Auction Log'!$D$5:$D$304,"<>",'Auction Log'!$E$5:$E$304,">0")=0,"",IFERROR(INDEX('Auction Log'!$E$5:$E$304,MATCH(1,('Auction Log'!$B$5:$B$304=A36)*('Auction Log'!$D$5:$D$304<>"")*('Auction Log'!$E$5:$E$304>0),0)),"")) | F36: CAR | G36: WR | H36: 5 | I36: 32 | J36: 4 | K36: 234 | L36: 236 | M36: 24 | N36: 28 | O36: -1 | P36: 2 | Q36: 0 | R36: 30 | S36: 27 | T36: HOLD | V36: =IF(E36="","",R36-E36) | W36: YES | X36: =IF(AND(D36="Available",R36>=55),ROW(),9999) -> 9999 | Y36: =IF(AND(D36="Available",R36>=40,R36<55),ROW(),9999) -> 9999 | Z36: =IF(AND(D36="Available",R36>=25,R36<40),ROW(),9999) -> 36 | AA36: =IF(K36="","",IF(L36="",K36,ROUND(AVERAGE(K36,L36),0))) -> 235
A37: Josh Jacobs | B37: =R37-N37 -> 1 | C37: =IF(B37>=5,"SMASH BUY",IF(B37>=2,"BUY",IF(B37>=-1,"NEUTRAL",IF(B37>=-4,"AVOID","DO NOT BID")))) -> NEUTRAL | D37: =IF(COUNTIFS('Auction Log'!$B$5:$B$304,A37,'Auction Log'!$D$5:$D$304,"<>",'Auction Log'!$E$5:$E$304,">0")=0,"Available",IFERROR(INDEX('Auction Log'!$D$5:$D$304,MATCH(1,('Auction Log'!$B$5:$B$304=A37)*('Auction Log'!$D$5:$D$304<>"")*('Auction Log'!$E$5:$E$304>0),0)),"SOLD")) -> Available | E37: =IF(COUNTIFS('Auction Log'!$B$5:$B$304,A37,'Auction Log'!$D$5:$D$304,"<>",'Auction Log'!$E$5:$E$304,">0")=0,"",IFERROR(INDEX('Auction Log'!$E$5:$E$304,MATCH(1,('Auction Log'!$B$5:$B$304=A37)*('Auction Log'!$D$5:$D$304<>"")*('Auction Log'!$E$5:$E$304>0),0)),"")) | F37: GB | G37: RB | H37: 11 | I37: 43 | J37: 5 | K37: 249 | L37: 259 | M37: 27 | N37: 29 | O37: -1 | P37: 1 | Q37: 0 | R37: 30 | S37: 27 | T37: HOLD | V37: =IF(E37="","",R37-E37) | W37: YES | X37: =IF(AND(D37="Available",R37>=55),ROW(),9999) -> 9999 | Y37: =IF(AND(D37="Available",R37>=40,R37<55),ROW(),9999) -> 9999 | Z37: =IF(AND(D37="Available",R37>=25,R37<40),ROW(),9999) -> 37 | AA37: =IF(K37="","",IF(L37="",K37,ROUND(AVERAGE(K37,L37),0))) -> 254
A38: Jeremiyah Love | B38: =R38-N38 -> -1 | C38: =IF(B38>=5,"SMASH BUY",IF(B38>=2,"BUY",IF(B38>=-1,"NEUTRAL",IF(B38>=-4,"AVOID","DO NOT BID")))) -> NEUTRAL | D38: =IF(COUNTIFS('Auction Log'!$B$5:$B$304,A38,'Auction Log'!$D$5:$D$304,"<>",'Auction Log'!$E$5:$E$304,">0")=0,"Available",IFERROR(INDEX('Auction Log'!$D$5:$D$304,MATCH(1,('Auction Log'!$B$5:$B$304=A38)*('Auction Log'!$D$5:$D$304<>"")*('Auction Log'!$E$5:$E$304>0),0)),"SOLD")) -> Available | E38: =IF(COUNTIFS('Auction Log'!$B$5:$B$304,A38,'Auction Log'!$D$5:$D$304,"<>",'Auction Log'!$E$5:$E$304,">0")=0,"",IFERROR(INDEX('Auction Log'!$E$5:$E$304,MATCH(1,('Auction Log'!$B$5:$B$304=A38)*('Auction Log'!$D$5:$D$304<>"")*('Auction Log'!$E$5:$E$304>0),0)),"")) | F38: ARI | G38: RB | H38: 14 | I38: 41 | J38: 5 | K38: 255 | L38: 278 | M38: 42 | N38: 30 | O38: 2 | P38: 1 | Q38: 5 | R38: 29 | S38: 26 | T38: DRAIN | U38: High ankle - light agility only 8/26; est. return Sep 13 (ESPN). Week 1 risk real — fade unless steal. | V38: =IF(E38="","",R38-E38) | W38: YES | X38: =IF(AND(D38="Available",R38>=55),ROW(),9999) -> 9999 | Y38: =IF(AND(D38="Available",R38>=40,R38<55),ROW(),9999) -> 9999 | Z38: =IF(AND(D38="Available",R38>=25,R38<40),ROW(),9999) -> 38 | AA38: =IF(K38="","",IF(L38="",K38,ROUND(AVERAGE(K38,L38),0))) -> 267
A39: Breece Hall | B39: =R39-N39 -> 0 | C39: =IF(B39>=5,"SMASH BUY",IF(B39>=2,"BUY",IF(B39>=-1,"NEUTRAL",IF(B39>=-4,"AVOID","DO NOT BID")))) -> NEUTRAL | D39: =IF(COUNTIFS('Auction Log'!$B$5:$B$304,A39,'Auction Log'!$D$5:$D$304,"<>",'Auction Log'!$E$5:$E$304,">0")=0,"Available",IFERROR(INDEX('Auction Log'!$D$5:$D$304,MATCH(1,('Auction Log'!$B$5:$B$304=A39)*('Auction Log'!$D$5:$D$304<>"")*('Auction Log'!$E$5:$E$304>0),0)),"SOLD")) -> Available | E39: =IF(COUNTIFS('Auction Log'!$B$5:$B$304,A39,'Auction Log'!$D$5:$D$304,"<>",'Auction Log'!$E$5:$E$304,">0")=0,"",IFERROR(INDEX('Auction Log'!$E$5:$E$304,MATCH(1,('Auction Log'!$B$5:$B$304=A39)*('Auction Log'!$D$5:$D$304<>"")*('Auction Log'!$E$5:$E$304>0),0)),"")) | F39: NYJ | G39: RB | H39: 13 | I39: 39 | J39: 5 | K39: 245 | L39: 274 | M39: 32 | N39: 28 | O39: 1 | P39: 2 | Q39: 4 | R39: 28 | S39: 25 | T39: DRAIN | U39: Groin - side agility only 8/24; earlier 2–3 week miss outlook (ESPN). Discount only — early-season hole. | V39: =IF(E39="","",R39-E39) | W39: YES | X39: =IF(AND(D39="Available",R39>=55),ROW(),9999) -> 9999 | Y39: =IF(AND(D39="Available",R39>=40,R39<55),ROW(),9999) -> 9999 | Z39: =IF(AND(D39="Available",R39>=25,R39<40),ROW(),9999) -> 39 | AA39: =IF(K39="","",IF(L39="",K39,ROUND(AVERAGE(K39,L39),0))) -> 260
A40: Javonte Williams | B40: =R40-N40 -> 3 | C40: =IF(B40>=5,"SMASH BUY",IF(B40>=2,"BUY",IF(B40>=-1,"NEUTRAL",IF(B40>=-4,"AVOID","DO NOT BID")))) -> BUY | D40: =IF(COUNTIFS('Auction Log'!$B$5:$B$304,A40,'Auction Log'!$D$5:$D$304,"<>",'Auction Log'!$E$5:$E$304,">0")=0,"Available",IFERROR(INDEX('Auction Log'!$D$5:$D$304,MATCH(1,('Auction Log'!$B$5:$B$304=A40)*('Auction Log'!$D$5:$D$304<>"")*('Auction Log'!$E$5:$E$304>0),0)),"SOLD")) -> Available | E40: =IF(COUNTIFS('Auction Log'!$B$5:$B$304,A40,'Auction Log'!$D$5:$D$304,"<>",'Auction Log'!$E$5:$E$304,">0")=0,"",IFERROR(INDEX('Auction Log'!$E$5:$E$304,MATCH(1,('Auction Log'!$B$5:$B$304=A40)*('Auction Log'!$D$5:$D$304<>"")*('Auction Log'!$E$5:$E$304>0),0)),"")) | F40: DAL | G40: RB | H40: 14 | I40: 44 | J40: 5 | K40: 234 | L40: 259 | M40: 26 | N40: 25 | O40: 0 | P40: 2 | Q40: 0 | R40: 28 | S40: 25 | T40: TARGET | V40: =IF(E40="","",R40-E40) | W40: YES | X40: =IF(AND(D40="Available",R40>=55),ROW(),9999) -> 9999 | Y40: =IF(AND(D40="Available",R40>=40,R40<55),ROW(),9999) -> 9999 | Z40: =IF(AND(D40="Available",R40>=25,R40<40),ROW(),9999) -> 40 | AA40: =IF(K40="","",IF(L40="",K40,ROUND(AVERAGE(K40,L40),0))) -> 247
A41: Kyren Williams | B41: =R41-N41 -> 0 | C41: =IF(B41>=5,"SMASH BUY",IF(B41>=2,"BUY",IF(B41>=-1,"NEUTRAL",IF(B41>=-4,"AVOID","DO NOT BID")))) -> NEUTRAL | D41: =IF(COUNTIFS('Auction Log'!$B$5:$B$304,A41,'Auction Log'!$D$5:$D$304,"<>",'Auction Log'!$E$5:$E$304,">0")=0,"Available",IFERROR(INDEX('Auction Log'!$D$5:$D$304,MATCH(1,('Auction Log'!$B$5:$B$304=A41)*('Auction Log'!$D$5:$D$304<>"")*('Auction Log'!$E$5:$E$304>0),0)),"SOLD")) -> Available | E41: =IF(COUNTIFS('Auction Log'!$B$5:$B$304,A41,'Auction Log'!$D$5:$D$304,"<>",'Auction Log'!$E$5:$E$304,">0")=0,"",IFERROR(INDEX('Auction Log'!$E$5:$E$304,MATCH(1,('Auction Log'!$B$5:$B$304=A41)*('Auction Log'!$D$5:$D$304<>"")*('Auction Log'!$E$5:$E$304>0),0)),"")) | F41: LAR | G41: RB | H41: 11 | I41: 42 | J41: 5 | K41: 240 | L41: 232 | M41: 21 | N41: 27 | O41: -2 | P41: 1 | Q41: 0 | R41: 27 | S41: 24 | T41: HOLD | V41: =IF(E41="","",R41-E41) | W41: YES | X41: =IF(AND(D41="Available",R41>=55),ROW(),9999) -> 9999 | Y41: =IF(AND(D41="Available",R41>=40,R41<55),ROW(),9999) -> 9999 | Z41: =IF(AND(D41="Available",R41>=25,R41<40),ROW(),9999) -> 41 | AA41: =IF(K41="","",IF(L41="",K41,ROUND(AVERAGE(K41,L41),0))) -> 236
A42: Ladd McConkey | B42: =R42-N42 -> 1 | C42: =IF(B42>=5,"SMASH BUY",IF(B42>=2,"BUY",IF(B42>=-1,"NEUTRAL",IF(B42>=-4,"AVOID","DO NOT BID")))) -> NEUTRAL | D42: =IF(COUNTIFS('Auction Log'!$B$5:$B$304,A42,'Auction Log'!$D$5:$D$304,"<>",'Auction Log'!$E$5:$E$304,">0")=0,"Available",IFERROR(INDEX('Auction Log'!$D$5:$D$304,MATCH(1,('Auction Log'!$B$5:$B$304=A42)*('Auction Log'!$D$5:$D$304<>"")*('Auction Log'!$E$5:$E$304>0),0)),"SOLD")) -> Available | E42: =IF(COUNTIFS('Auction Log'!$B$5:$B$304,A42,'Auction Log'!$D$5:$D$304,"<>",'Auction Log'!$E$5:$E$304,">0")=0,"",IFERROR(INDEX('Auction Log'!$E$5:$E$304,MATCH(1,('Auction Log'!$B$5:$B$304=A42)*('Auction Log'!$D$5:$D$304<>"")*('Auction Log'!$E$5:$E$304>0),0)),"")) | F42: LAC | G42: WR | H42: 7 | I42: 34 | J42: 4 | K42: 220 | L42: 221 | M42: 17 | N42: 24 | O42: -1 | P42: 1 | Q42: 0 | R42: 25 | S42: 22 | T42: HOLD | V42: =IF(E42="","",R42-E42) | W42: YES | X42: =IF(AND(D42="Available",R42>=55),ROW(),9999) -> 9999 | Y42: =IF(AND(D42="Available",R42>=40,R42<55),ROW(),9999) -> 9999 | Z42: =IF(AND(D42="Available",R42>=25,R42<40),ROW(),9999) -> 42 | AA42: =IF(K42="","",IF(L42="",K42,ROUND(AVERAGE(K42,L42),0))) -> 221
A43: Tee Higgins | B43: =R43-N43 -> 0 | C43: =IF(B43>=5,"SMASH BUY",IF(B43>=2,"BUY",IF(B43>=-1,"NEUTRAL",IF(B43>=-4,"AVOID","DO NOT BID")))) -> NEUTRAL | D43: =IF(COUNTIFS('Auction Log'!$B$5:$B$304,A43,'Auction Log'!$D$5:$D$304,"<>",'Auction Log'!$E$5:$E$304,">0")=0,"Available",IFERROR(INDEX('Auction Log'!$D$5:$D$304,MATCH(1,('Auction Log'!$B$5:$B$304=A43)*('Auction Log'!$D$5:$D$304<>"")*('Auction Log'!$E$5:$E$304>0),0)),"SOLD")) -> Available | E43: =IF(COUNTIFS('Auction Log'!$B$5:$B$304,A43,'Auction Log'!$D$5:$D$304,"<>",'Auction Log'!$E$5:$E$304,">0")=0,"",IFERROR(INDEX('Auction Log'!$E$5:$E$304,MATCH(1,('Auction Log'!$B$5:$B$304=A43)*('Auction Log'!$D$5:$D$304<>"")*('Auction Log'!$E$5:$E$304>0),0)),"")) | F43: CIN | G43: WR | H43: 6 | I43: 35 | J43: 4 | K43: 222 | L43: 219 | M43: 15 | N43: 25 | O43: -2 | P43: 1 | Q43: 0 | R43: 25 | S43: 22 | T43: HOLD | V43: =IF(E43="","",R43-E43) | W43: YES | X43: =IF(AND(D43="Available",R43>=55),ROW(),9999) -> 9999 | Y43: =IF(AND(D43="Available",R43>=40,R43<55),ROW(),9999) -> 9999 | Z43: =IF(AND(D43="Available",R43>=25,R43<40),ROW(),9999) -> 43 | AA43: =IF(K43="","",IF(L43="",K43,ROUND(AVERAGE(K43,L43),0))) -> 221
A44: Travis Etienne Jr. | B44: =R44-N44 -> 0 | C44: =IF(B44>=5,"SMASH BUY",IF(B44>=2,"BUY",IF(B44>=-1,"NEUTRAL",IF(B44>=-4,"AVOID","DO NOT BID")))) -> NEUTRAL | D44: =IF(COUNTIFS('Auction Log'!$B$5:$B$304,A44,'Auction Log'!$D$5:$D$304,"<>",'Auction Log'!$E$5:$E$304,">0")=0,"Available",IFERROR(INDEX('Auction Log'!$D$5:$D$304,MATCH(1,('Auction Log'!$B$5:$B$304=A44)*('Auction Log'!$D$5:$D$304<>"")*('Auction Log'!$E$5:$E$304>0),0)),"SOLD")) -> Available | E44: =IF(COUNTIFS('Auction Log'!$B$5:$B$304,A44,'Auction Log'!$D$5:$D$304,"<>",'Auction Log'!$E$5:$E$304,">0")=0,"",IFERROR(INDEX('Auction Log'!$E$5:$E$304,MATCH(1,('Auction Log'!$B$5:$B$304=A44)*('Auction Log'!$D$5:$D$304<>"")*('Auction Log'!$E$5:$E$304>0),0)),"")) | F44: NO | G44: RB | H44: 8 | I44: 48 | J44: 5 | K44: 235 | L44: 246 | M44: 22 | N44: 25 | O44: -2 | P44: 1 | Q44: 0 | R44: 25 | S44: 22 | T44: HOLD | V44: =IF(E44="","",R44-E44) | W44: YES | X44: =IF(AND(D44="Available",R44>=55),ROW(),9999) -> 9999 | Y44: =IF(AND(D44="Available",R44>=40,R44<55),ROW(),9999) -> 9999 | Z44: =IF(AND(D44="Available",R44>=25,R44<40),ROW(),9999) -> 44 | AA44: =IF(K44="","",IF(L44="",K44,ROUND(AVERAGE(K44,L44),0))) -> 241
A45: Cam Skattebo | B45: =R45-N45 -> 0 | C45: =IF(B45>=5,"SMASH BUY",IF(B45>=2,"BUY",IF(B45>=-1,"NEUTRAL",IF(B45>=-4,"AVOID","DO NOT BID")))) -> NEUTRAL | D45: =IF(COUNTIFS('Auction Log'!$B$5:$B$304,A45,'Auction Log'!$D$5:$D$304,"<>",'Auction Log'!$E$5:$E$304,">0")=0,"Available",IFERROR(INDEX('Auction Log'!$D$5:$D$304,MATCH(1,('Auction Log'!$B$5:$B$304=A45)*('Auction Log'!$D$5:$D$304<>"")*('Auction Log'!$E$5:$E$304>0),0)),"SOLD")) -> Available | E45: =IF(COUNTIFS('Auction Log'!$B$5:$B$304,A45,'Auction Log'!$D$5:$D$304,"<>",'Auction Log'!$E$5:$E$304,">0")=0,"",IFERROR(INDEX('Auction Log'!$E$5:$E$304,MATCH(1,('Auction Log'!$B$5:$B$304=A45)*('Auction Log'!$D$5:$D$304<>"")*('Auction Log'!$E$5:$E$304>0),0)),"")) | F45: NYG | G45: RB | H45: 8 | I45: 56 | J45: 6 | K45: 235 | L45: 230 | M45: 20 | N45: 25 | O45: -2 | P45: 1 | Q45: 0 | R45: 25 | S45: 22 | T45: HOLD | V45: =IF(E45="","",R45-E45) | W45: YES | X45: =IF(AND(D45="Available",R45>=55),ROW(),9999) -> 9999 | Y45: =IF(AND(D45="Available",R45>=40,R45<55),ROW(),9999) -> 9999 | Z45: =IF(AND(D45="Available",R45>=25,R45<40),ROW(),9999) -> 45 | AA45: =IF(K45="","",IF(L45="",K45,ROUND(AVERAGE(K45,L45),0))) -> 233
A46: Davante Adams | B46: =R46-N46 -> -1 | C46: =IF(B46>=5,"SMASH BUY",IF(B46>=2,"BUY",IF(B46>=-1,"NEUTRAL",IF(B46>=-4,"AVOID","DO NOT BID")))) -> NEUTRAL | D46: =IF(COUNTIFS('Auction Log'!$B$5:$B$304,A46,'Auction Log'!$D$5:$D$304,"<>",'Auction Log'!$E$5:$E$304,">0")=0,"Available",IFERROR(INDEX('Auction Log'!$D$5:$D$304,MATCH(1,('Auction Log'!$B$5:$B$304=A46)*('Auction Log'!$D$5:$D$304<>"")*('Auction Log'!$E$5:$E$304>0),0)),"SOLD")) -> Available | E46: =IF(COUNTIFS('Auction Log'!$B$5:$B$304,A46,'Auction Log'!$D$5:$D$304,"<>",'Auction Log'!$E$5:$E$304,">0")=0,"",IFERROR(INDEX('Auction Log'!$E$5:$E$304,MATCH(1,('Auction Log'!$B$5:$B$304=A46)*('Auction Log'!$D$5:$D$304<>"")*('Auction Log'!$E$5:$E$304>0),0)),"")) | F46: LAR | G46: WR | H46: 11 | I46: 49 | J46: 5 | K46: 222 | L46: 232 | M46: 18 | N46: 25 | O46: -3 | P46: 1 | Q46: 0 | R46: 24 | S46: 22 | T46: DRAIN | V46: =IF(E46="","",R46-E46) | W46: YES | X46: =IF(AND(D46="Available",R46>=55),ROW(),9999) -> 9999 | Y46: =IF(AND(D46="Available",R46>=40,R46<55),ROW(),9999) -> 9999 | Z46: =IF(AND(D46="Available",R46>=25,R46<40),ROW(),9999) -> 9999 | AA46: =IF(K46="","",IF(L46="",K46,ROUND(AVERAGE(K46,L46),0))) -> 227
A47: Jaylen Waddle | B47: =R47-N47 -> 2 | C47: =IF(B47>=5,"SMASH BUY",IF(B47>=2,"BUY",IF(B47>=-1,"NEUTRAL",IF(B47>=-4,"AVOID","DO NOT BID")))) -> BUY | D47: =IF(COUNTIFS('Auction Log'!$B$5:$B$304,A47,'Auction Log'!$D$5:$D$304,"<>",'Auction Log'!$E$5:$E$304,">0")=0,"Available",IFERROR(INDEX('Auction Log'!$D$5:$D$304,MATCH(1,('Auction Log'!$B$5:$B$304=A47)*('Auction Log'!$D$5:$D$304<>"")*('Auction Log'!$E$5:$E$304>0),0)),"SOLD")) -> Available | E47: =IF(COUNTIFS('Auction Log'!$B$5:$B$304,A47,'Auction Log'!$D$5:$D$304,"<>",'Auction Log'!$E$5:$E$304,">0")=0,"",IFERROR(INDEX('Auction Log'!$E$5:$E$304,MATCH(1,('Auction Log'!$B$5:$B$304=A47)*('Auction Log'!$D$5:$D$304<>"")*('Auction Log'!$E$5:$E$304>0),0)),"")) | F47: DEN | G47: WR | H47: 10 | I47: 33 | J47: 4 | K47: 210 | L47: 213 | M47: 15 | N47: 21 | O47: 0 | P47: 1 | Q47: 0 | R47: 23 | S47: 21 | T47: TARGET | V47: =IF(E47="","",R47-E47) | W47: YES | X47: =IF(AND(D47="Available",R47>=55),ROW(),9999) -> 9999 | Y47: =IF(AND(D47="Available",R47>=40,R47<55),ROW(),9999) -> 9999 | Z47: =IF(AND(D47="Available",R47>=25,R47<40),ROW(),9999) -> 9999 | AA47: =IF(K47="","",IF(L47="",K47,ROUND(AVERAGE(K47,L47),0))) -> 212
A48: Emeka Egbuka | B48: =R48-N48 -> -3 | C48: =IF(B48>=5,"SMASH BUY",IF(B48>=2,"BUY",IF(B48>=-1,"NEUTRAL",IF(B48>=-4,"AVOID","DO NOT BID")))) -> AVOID | D48: =IF(COUNTIFS('Auction Log'!$B$5:$B$304,A48,'Auction Log'!$D$5:$D$304,"<>",'Auction Log'!$E$5:$E$304,">0")=0,"Available",IFERROR(INDEX('Auction Log'!$D$5:$D$304,MATCH(1,('Auction Log'!$B$5:$B$304=A48)*('Auction Log'!$D$5:$D$304<>"")*('Auction Log'!$E$5:$E$304>0),0)),"SOLD")) -> Available | E48: =IF(COUNTIFS('Auction Log'!$B$5:$B$304,A48,'Auction Log'!$D$5:$D$304,"<>",'Auction Log'!$E$5:$E$304,">0")=0,"",IFERROR(INDEX('Auction Log'!$E$5:$E$304,MATCH(1,('Auction Log'!$B$5:$B$304=A48)*('Auction Log'!$D$5:$D$304<>"")*('Auction Log'!$E$5:$E$304>0),0)),"")) | F48: TB | G48: WR | H48: 10 | I48: 40 | J48: 5 | K48: 228 | L48: 229 | M48: 19 | N48: 26 | O48: -2 | P48: 2 | Q48: 4 | R48: 23 | S48: 21 | T48: DRAIN | U48: Toe - not participating in practice as of 8/25 (ESPN). Soft pass / require big discount. | V48: =IF(E48="","",R48-E48) | W48: YES | X48: =IF(AND(D48="Available",R48>=55),ROW(),9999) -> 9999 | Y48: =IF(AND(D48="Available",R48>=40,R48<55),ROW(),9999) -> 9999 | Z48: =IF(AND(D48="Available",R48>=25,R48<40),ROW(),9999) -> 9999 | AA48: =IF(K48="","",IF(L48="",K48,ROUND(AVERAGE(K48,L48),0))) -> 229
...

Sheet Auction Log
A1: LIVE ENTRY + AUCTION LOG
A2: Use the first bright-green row. Tab: Player > Winner > Price > Roster Slot. Ctrl+Down moves quickly through the log.
A4: Nom # | B4: Player | C4: Pos | D4: Winner | E4: Price | F4: Roster Slot | G4: My Max | H4: Sale Value | I4: Note | J4: Entry Check | K4: Projection
A5: =IF(B5="","",ROW()-4) | C5: =IFERROR(INDEX('Player Board'!$G$5:$G$304,MATCH(B5,'Player Board'!$A$5:$A$304,0)),"") | G5: =IFERROR(INDEX('Player Board'!$R$5:$R$304,MATCH(B5,'Player Board'!$A$5:$A$304,0)),"") | H5: =IF(E5="","",G5-E5) | J5: =IF(B5="","",IF(A5=MAX($A$5:$A$304),"LAST — CLEAR INPUTS TO UNDO",IF(AND(D5<>"",E5<>""),"LOGGED","INCOMPLETE"))) | K5: =IFERROR(INDEX('Player Board'!$AA$5:$AA$304,MATCH(B5,'Player Board'!$A$5:$A$304,0)),"")
A6: =IF(B6="","",ROW()-4) | C6: =IFERROR(INDEX('Player Board'!$G$5:$G$304,MATCH(B6,'Player Board'!$A$5:$A$304,0)),"") | G6: =IFERROR(INDEX('Player Board'!$R$5:$R$304,MATCH(B6,'Player Board'!$A$5:$A$304,0)),"") | H6: =IF(E6="","",G6-E6) | J6: =IF(B6="","",IF(A6=MAX($A$5:$A$304),"LAST — CLEAR INPUTS TO UNDO",IF(AND(D6<>"",E6<>""),"LOGGED","INCOMPLETE"))) | K6: =IFERROR(INDEX('Player Board'!$AA$5:$AA$304,MATCH(B6,'Player Board'!$A$5:$A$304,0)),"")
A7: =IF(B7="","",ROW()-4) | C7: =IFERROR(INDEX('Player Board'!$G$5:$G$304,MATCH(B7,'Player Board'!$A$5:$A$304,0)),"") | G7: =IFERROR(INDEX('Player Board'!$R$5:$R$304,MATCH(B7,'Player Board'!$A$5:$A$304,0)),"") | H7: =IF(E7="","",G7-E7) | J7: =IF(B7="","",IF(A7=MAX($A$5:$A$304),"LAST — CLEAR INPUTS TO UNDO",IF(AND(D7<>"",E7<>""),"LOGGED","INCOMPLETE"))) | K7: =IFERROR(INDEX('Player Board'!$AA$5:$AA$304,MATCH(B7,'Player Board'!$A$5:$A$304,0)),"")
A8: =IF(B8="","",ROW()-4) | C8: =IFERROR(INDEX('Player Board'!$G$5:$G$304,MATCH(B8,'Player Board'!$A$5:$A$304,0)),"") | G8: =IFERROR(INDEX('Player Board'!$R$5:$R$304,MATCH(B8,'Player Board'!$A$5:$A$304,0)),"") | H8: =IF(E8="","",G8-E8) | J8: =IF(B8="","",IF(A8=MAX($A$5:$A$304),"LAST — CLEAR INPUTS TO UNDO",IF(AND(D8<>"",E8<>""),"LOGGED","INCOMPLETE"))) | K8: =IFERROR(INDEX('Player Board'!$AA$5:$AA$304,MATCH(B8,'Player Board'!$A$5:$A$304,0)),"")
A9: =IF(B9="","",ROW()-4) | C9: =IFERROR(INDEX('Player Board'!$G$5:$G$304,MATCH(B9,'Player Board'!$A$5:$A$304,0)),"") | G9: =IFERROR(INDEX('Player Board'!$R$5:$R$304,MATCH(B9,'Player Board'!$A$5:$A$304,0)),"") | H9: =IF(E9="","",G9-E9) | J9: =IF(B9="","",IF(A9=MAX($A$5:$A$304),"LAST — CLEAR INPUTS TO UNDO",IF(AND(D9<>"",E9<>""),"LOGGED","INCOMPLETE"))) | K9: =IFERROR(INDEX('Player Board'!$AA$5:$AA$304,MATCH(B9,'Player Board'!$A$5:$A$304,0)),"")
A10: =IF(B10="","",ROW()-4) | C10: =IFERROR(INDEX('Player Board'!$G$5:$G$304,MATCH(B10,'Player Board'!$A$5:$A$304,0)),"") | G10: =IFERROR(INDEX('Player Board'!$R$5:$R$304,MATCH(B10,'Player Board'!$A$5:$A$304,0)),"") | H10: =IF(E10="","",G10-E10) | J10: =IF(B10="","",IF(A10=MAX($A$5:$A$304),"LAST — CLEAR INPUTS TO UNDO",IF(AND(D10<>"",E10<>""),"LOGGED","INCOMPLETE"))) | K10: =IFERROR(INDEX('Player Board'!$AA$5:$AA$304,MATCH(B10,'Player Board'!$A$5:$A$304,0)),"")
A11: =IF(B11="","",ROW()-4) | C11: =IFERROR(INDEX('Player Board'!$G$5:$G$304,MATCH(B11,'Player Board'!$A$5:$A$304,0)),"") | G11: =IFERROR(INDEX('Player Board'!$R$5:$R$304,MATCH(B11,'Player Board'!$A$5:$A$304,0)),"") | H11: =IF(E11="","",G11-E11) | J11: =IF(B11="","",IF(A11=MAX($A$5:$A$304),"LAST — CLEAR INPUTS TO UNDO",IF(AND(D11<>"",E11<>""),"LOGGED","INCOMPLETE"))) | K11: =IFERROR(INDEX('Player Board'!$AA$5:$AA$304,MATCH(B11,'Player Board'!$A$5:$A$304,0)),"")
